Workbook

Sheet Models
A1: Identifier | B1: Model | C1: Pipeline/Prompt | D1: Hyperparameter tuning | E1: Hyperparameter config
A2: H.# | B2: Manual | C2: N/A | D2: N/A | E2: N/A
A3: L0.# | L0_ii.# | L0_iii.# | L0_iv.# | B3: Meta/LLaMa-3.1 | C3: Base | D3: Optimal | E3: CHECK_APPLICABILITY_CHAIN: {top_p: 0.95; temperature: 0.6} SEARCH_DOMAIN_ELEMENTS_CHAIN: {top_p: 0.95; temperature: 0.65} GENERATE_CHAIN: {top_p: 0.95; temperature: 0.7} FORMAT_CHAIN: {top_p: 0.95; temperature: 0.5}
A4: L1.# | C4: Base | D4: Low temperature | E4: CHECK_APPLICABILITY_CHAIN: {top_p: 0.95; temperature: 0.6} SEARCH_DOMAIN_ELEMENTS_CHAIN: {top_p: 0.85; temperature: 0.55} GENERATE_CHAIN: {top_p: 0.85; temperature: 0.6} FORMAT_CHAIN: {top_p: 0.95; temperature: 0.5}
A5: L2.# | C5: Base | D5: High temperature | E5: CHECK_APPLICABILITY_CHAIN: {top_p: 0.95; temperature: 0.6} SEARCH_DOMAIN_ELEMENTS_CHAIN: {top_p: 0.95; temperature: 0.75} GENERATE_CHAIN: {top_p: 0.95; temperature: 0.8} FORMAT_CHAIN: {top_p: 0.95; temperature: 0.5}
A6: L3.# | C6: Branched (high sigma) | D6: Optimal | E6: CHECK_APPLICABILITY_CHAIN (x1): {top_p: 0.95; temperature: 0.6} SEARCH_DOMAIN_ELEMENTS_CHAIN (x4): {top_p: 0.95; temperature: 0.65} GENERATE_CHAIN (x4): {top_p: 0.95; temperature: 0.7} COALESCE_CHAIN (x1): {top_p: 0.95; temperature: 0.6} FORMAT_CHAIN: {top_p: 0.95; temperature: 0.6}
A7: L4.# | C7: AiO | D7: Optimal | E7: GENERATE_CHAIN (x1): {top_p: 0.95; temperature: 0.7} FORMAT_CHAIN: {top_p: 0.95; temperature: 0.5}
A8: L5.# | C8: Few shot | D8: Optimal | E8: CHECK_APPLICABILITY_CHAIN: {top_p: 0.95; temperature: 0.6} SEARCH_DOMAIN_ELEMENTS_CHAIN: {top_p: 0.95; temperature: 0.75} GENERATE_CHAIN: {top_p: 0.95; temperature: 0.8} FORMAT_CHAIN: {top_p: 0.95; temperature: 0.6}
A9: L0a.# | C9: No repetitions | D9: Optimal | E9: CHECK_APPLICABILITY_CHAIN: {top_p: 0.95; temperature: 0.6} SEARCH_DOMAIN_ELEMENTS_CHAIN: {top_p: 0.95; temperature: 0.65} GENERATE_CHAIN: {top_p: 0.95; temperature: 0.7} FORMAT_CHAIN: {top_p: 0.95; temperature: 0.5}
A10: L0b.# | C10: Simplified | D10: Optimal | E10: CHECK_APPLICABILITY_CHAIN: {top_p: 0.95; temperature: 0.6} SEARCH_DOMAIN_ELEMENTS_CHAIN: {top_p: 0.95; temperature: 0.65} GENERATE_CHAIN: {top_p: 0.95; temperature: 0.7} FORMAT_CHAIN: {top_p: 0.95; temperature: 0.5}
A11: Q0.# | Q0_ii.# | Q0_iii.# | Q0_iv.# | B11: Qwen/Qwen2-72B | C11: Base | D11: Optimal | E11: CHECK_APPLICABILITY_CHAIN: {top_p: 0.95; temperature: 0.6} SEARCH_DOMAIN_ELEMENTS_CHAIN: {top_p: 0.95; temperature: 0.65} GENERATE_CHAIN: {top_p: 0.95; temperature: 0.7} FORMAT_CHAIN: {top_p: 0.95; temperature: 0.5}
A12: Q1.# | D12: Low temperature | E12: CHECK_APPLICABILITY_CHAIN: {top_p: 0.95; temperature: 0.6} SEARCH_DOMAIN_ELEMENTS_CHAIN: {top_p: 0.85; temperature: 0.55} GENERATE_CHAIN: {top_p: 0.85; temperature: 0.6} FORMAT_CHAIN: {top_p: 0.95; temperature: 0.5}
A13: Q2.# | D13: High temperature | E13: CHECK_APPLICABILITY_CHAIN: {top_p: 0.95; temperature: 0.6} SEARCH_DOMAIN_ELEMENTS_CHAIN: {top_p: 0.95; temperature: 0.75} GENERATE_CHAIN: {top_p: 0.95; temperature: 0.8} FORMAT_CHAIN: {top_p: 0.95; temperature: 0.5}
A14: M0.# | M0_ii.# | M0_iii.# | M0_iv.# | B14: mistralai/Mixtral-8x22B | C14: Base | D14: Optimal | E14: CHECK_APPLICABILITY_CHAIN: {top_p: 0.95; temperature: 0.6} SEARCH_DOMAIN_ELEMENTS_CHAIN: {top_p: 0.95; temperature: 0.65} GENERATE_CHAIN: {top_p: 0.95; temperature: 0.7} FORMAT_CHAIN: {top_p: 0.95; temperature: 0.5}
A15: M1.# | D15: Low temperature | E15: CHECK_APPLICABILITY_CHAIN: {top_p: 0.95; temperature: 0.6} SEARCH_DOMAIN_ELEMENTS_CHAIN: {top_p: 0.85; temperature: 0.55} GENERATE_CHAIN: {top_p: 0.85; temperature: 0.6} FORMAT_CHAIN: {top_p: 0.95; temperature: 0.5}
A16: M2.# | D16: High temperature | E16: CHECK_APPLICABILITY_CHAIN: {top_p: 0.95; temperature: 0.6} SEARCH_DOMAIN_ELEMENTS_CHAIN: {top_p: 0.95; temperature: 0.75} GENERATE_CHAIN: {top_p: 0.95; temperature: 0.8} FORMAT_CHAIN: {top_p: 0.95; temperature: 0.5}
A17: G0.# | G0_ii.# | G0_iii.# | G0_iv.# | B17: GPT-4-Turbo | C17: Base | D17: Optimal | E17: CHECK_APPLICABILITY_CHAIN: {temperature: 0.6} SEARCH_DOMAIN_ELEMENTS_CHAIN: {temperature: 0.65} GENERATE_CHAIN: {temperature: 0.7} FORMAT_CHAIN: {temperature: 0.5}
A18: G1.# | D18: Low temperature | E18: CHECK_APPLICABILITY_CHAIN: {temperature: 0.6} SEARCH_DOMAIN_ELEMENTS_CHAIN: { temperature: 0.55} GENERATE_CHAIN: {temperature: 0.6} FORMAT_CHAIN: {temperature: 0.5}
A19: G2.# | D19: High temperature | E19: CHECK_APPLICABILITY_CHAIN: {temperature: 0.6} SEARCH_DOMAIN_ELEMENTS_CHAIN: {temperature: 0.75} GENERATE_CHAIN: {temperature: 0.8} FORMAT_CHAIN: {temperature: 0.5}

Sheet Summary
B1: H | C1: L0 | D1: L1 | E1: L2 | F1: L3 | G1: L4 | H1: L5 | I1: Q0 | J1: Q1 | K1: Q2 | L1: M0 | M1: M1 | N1: M2 | O1: G0 | P1: G1 | Q1: G2 | R1: L0a | S1: L0b
A2: Covered (H) | B2: 30 | C2: ='{C} Human to X'!D33 | D2: ='{C} Human to X'!L33 | E2: ='{C} Human to X'!N33 | F2: ='{C} Human to X'!P33 | G2: ='{C} Human to X'!S33 | H2: ='{C} Human to X'!U33 | I2: ='{C} Human to X'!W33 | J2: ='{C} Human to X'!AE33 | K2: ='{C} Human to X'!AG33 | L2: ='{C} Human to X'!AI33 | M2: ='{C} Human to X'!AQ33 | N2: ='{C} Human to X'!AS33 | O2: ='{C} Human to X'!AU33 | P2: ='{C} Human to X'!BC33 | Q2: ='{C} Human to X'!BE33 | R2: ='{C} Human to X'!BG33 | S2: ='{C} Human to X'!BI33
A3: Uncovered (H) | B3: 0 | C3: ='{C} Human to X'!D34 | D3: ='{C} Human to X'!L34 | E3: ='{C} Human to X'!N34 | F3: ='{C} Human to X'!P34 | G3: ='{C} Human to X'!S34 | H3: ='{C} Human to X'!U34 | I3: ='{C} Human to X'!W34 | J3: ='{C} Human to X'!AE34 | K3: ='{C} Human to X'!AG34 | L3: ='{C} Human to X'!AI34 | M3: ='{C} Human to X'!AQ34 | N3: ='{C} Human to X'!AS34 | O3: ='{C} Human to X'!AU34 | P3: ='{C} Human to X'!BC34 | Q3: ='{C} Human to X'!BE34 | R3: ='{C} Human to X'!BG34 | S3: ='{C} Human to X'!BI34
A4: Partial (H) | B4: 0 | C4: ='{C} Human to X'!D35 | D4: ='{C} Human to X'!L35 | E4: ='{C} Human to X'!N35 | F4: ='{C} Human to X'!P35 | G4: ='{C} Human to X'!S35 | H4: ='{C} Human to X'!U35 | I4: ='{C} Human to X'!W35 | J4: ='{C} Human to X'!AE35 | K4: ='{C} Human to X'!AG35 | L4: ='{C} Human to X'!AI35 | M4: ='{C} Human to X'!AQ35 | N4: ='{C} Human to X'!AS35 | O4: ='{C} Human to X'!AU35 | P4: ='{C} Human to X'!BC35 | Q4: ='{C} Human to X'!BE35 | R4: ='{C} Human to X'!BG35 | S4: ='{C} Human to X'!BI35
A5: Total (H) | B5: =B2+B3+B4 | C5: =C2+C3+C4 | D5: =D2+D3+D4 | E5: =E2+E3+E4 | F5: =F2+F3+F4 | G5: =G2+G3+G4 | H5: =H2+H3+H4 | I5: =I2+I3+I4 | ... S5: =S2+S3+S4
A6: Hallucinations | B6: 0 | C6: ='{C} L0'!F35 | D6: ='{C} L1'!F40 | E6: ='{C} L2'!F35 | F6: ='{C} L3'!F127 | G6: ='{C} L4'!F37 | H6: ='{C} L5'!F42 | I6: ='{C} Q0'!F41 | J6: ='{C} Q1'!F23 | K6: ='{C} Q2'!F30 | L6: ='{C} M0'!F45 | M6: ='{C} M1'!F35 | N6: ='{C} M2'!F40 | O6: ='{C} G0'!F25 | P6: ='{C} G1'!F31 | Q6: ='{C} G2'!F29 | R6: ='{C} L0a'!F45 | S6: ='{C} L0b'!F46
A7: Partial hallucinations | B7: 0 | C7: ='{C} L0'!F36 | D7: ='{C} L1'!F41 | E7: ='{C} L2'!F36 | F7: ='{C} L3'!F128 | G7: ='{C} L4'!F38 | H7: ='{C} L5'!F43 | I7: ='{C} Q0'!F42 | J7: ='{C} Q1'!F24 | K7: ='{C} Q2'!F31 | L7: ='{C} M0'!F46 | M7: ='{C} M1'!F36 | N7: ='{C} M2'!F41 | O7: ='{C} G0'!F26 | P7: ='{C} G1'!F32 | Q7: ='{C} G2'!F30 | R7: ='{C} L0a'!F46 | S7: ='{C} L0b'!F47
A9: GT = H
A10: Covered + Partial (H) | B10: =B2+B4 | C10: =C2+C4 | D10: =D2+D4 | E10: =E2+E4 | F10: =F2+F4 | G10: =G2+G4 | H10: =H2+H4 | I10: =I2+I4 | ... S10: =S2+S4
A11: Uncovered + Partial (H) | B11: =B3+B4 | C11: =C3+C4 | D11: =D3+D4 | E11: =E3+E4 | F11: =F3+F4 | G11: =G3+G4 | H11: =H3+H4 | I11: =I3+I4 | ... S11: =S3+S4
A12: Precision | B12: =B10/(B10+B6+B7) | C12: =C10/(C10+C6+C7) | D12: =D10/(D10+D6+D7) | E12: =E10/(E10+E6+E7) | F12: =F10/(F10+F6+F7) | G12: =G10/(G10+G6+G7) | H12: =H10/(H10+H6+H7) | I12: =I10/(I10+I6+I7) | ... S12: =S10/(S10+S6+S7)
A13: Recall worst | B13: =B2/(B2+B11) | C13: =C2/(C2+C11) | D13: =D2/(D2+D11) | E13: =E2/(E2+E11) | F13: =F2/(F2+F11) | G13: =G2/(G2+G11) | H13: =H2/(H2+H11) | I13: =I2/(I2+I11) | ... S13: =S2/(S2+S11)
A14: Recall best | B14: =B10/(B10+B3) | C14: =C10/(C10+C3) | D14: =D10/(D10+D3) | E14: =E10/(E10+E3) | F14: =F10/(F10+F3) | G14: =G10/(G10+G3) | H14: =H10/(H10+H3) | I14: =I10/(I10+I3) | ... S14: =S10/(S10+S3)
A16: GT = GS
A17: Total (GS) | B17: ='{C} GS to X'!$B$79 | C17: ='{C} GS to X'!$B$79 | D17: ='{C} GS to X'!$B$79 | E17: ='{C} GS to X'!$B$79 | F17: ='{C} GS to X'!$B$79 | G17: ='{C} GS to X'!$B$79 | H17: ='{C} GS to X'!$B$79 | I17: ='{C} GS to X'!$B$79 | ... Q17: ='{C} GS to X'!$B$79
A18: Discovered (GS) | B18: 0 | C18: ='{C} GS to X'!E79 | D18: ='{C} GS to X'!I79 | E18: ='{C} GS to X'!J79 | F18: ='{C} GS to X'!K79 | G18: ='{C} GS to X'!L79 | H18: ='{C} GS to X'!M79 | I18: ='{C} GS to X'!N79 | J18: ='{C} GS to X'!R79 | K18: ='{C} GS to X'!S79 | L18: ='{C} GS to X'!T79 | M18: ='{C} GS to X'!X79 | N18: ='{C} GS to X'!Y79 | O18: ='{C} GS to X'!Z79 | P18: ='{C} GS to X'!AD79 | Q18: ='{C} GS to X'!AE79
A19: Covered (GS) | B19: =B2+B18 | C19: =C2+C18 | D19: =D2+D18 | E19: =E2+E18 | F19: =F2+F18 | G19: =G2+G18 | H19: =H2+H18 | I19: =I2+I18 | ... Q19: =Q2+Q18
A20: Uncovered (GS) | B20: =B17-B19-B4 | C20: =C17-C19-C4 | D20: =D17-D19-D4 | E20: =E17-E19-E4 | F20: =F17-F19-F4 | G20: =G17-G19-G4 | H20: =H17-H19-H4 | I20: =I17-I19-I4 | ... Q20: =Q17-Q19-Q4
A21: Covered + Partial (GS) | B21: =B19+B4 | C21: =C19+C4 | D21: =D19+D4 | E21: =E19+E4 | F21: =F19+F4 | G21: =G19+G4 | H21: =H19+H4 | I21: =I19+I4 | ... Q21: =Q19+Q4
A22: Uncovered + Partial (GS) | B22: =B20+B4 | C22: =C20+C4 | D22: =D20+D4 | E22: =E20+E4 | F22: =F20+F4 | G22: =G20+G4 | H22: =H20+H4 | I22: =I20+I4 | ... Q22: =Q20+Q4
A23: Hallucinations | B23: =B6 | C23: =C6 | D23: =D6 | E23: =E6 | F23: =F6 | G23: =G6 | H23: =H6 | I23: =I6 | ... Q23: =Q6
A24: Partial hallucinations | B24: =B7 | C24: =C7 | D24: =D7 | E24: =E7 | F24: =F7 | G24: =G7 | H24: =H7 | I24: =I7 | ... Q24: =Q7
A26: Recall worst | B26: =B19/(B19+B22) | C26: =C19/(C19+C22) | D26: =D19/(D19+D22) | E26: =E19/(E19+E22) | F26: =F19/(F19+F22) | G26: =G19/(G19+G22) | H26: =H19/(H19+H22) | I26: =I19/(I19+I22) | ... Q26: =Q19/(Q19+Q22)
A27: Recall best | B27: =B21/(B21+B20) | C27: =C21/(C21+C20) | D27: =D21/(D21+D20) | E27: =E21/(E21+E20) | F27: =F21/(F21+F20) | G27: =G21/(G21+G20) | H27: =H21/(H21+H20) | I27: =I21/(I21+I20) | ... Q27: =Q21/(Q21+Q20)
A28: Precision | B28: =B21/(B21+B23+B24) | C28: =C21/(C21+C23+C24) | D28: =D21/(D21+D23+D24) | E28: =E21/(E21+E23+E24) | F28: =F21/(F21+F23+F24) | G28: =G21/(G21+G23+G24) | H28: =H21/(H21+H23+H24) | I28: =I21/(I21+I23+I24) | ... Q28: =Q21/(Q21+Q23+Q24)
A29: Recall gain worst | B29: =B26/$B26 | C29: =C26/$B26 | D29: =D26/$B26 | E29: =E26/$B26 | F29: =F26/$B26 | G29: =G26/$B26 | H29: =H26/$B26 | I29: =I26/$B26 | ... Q29: =Q26/$B26
A30: Recall gain best | B30: =B27/$B27 | C30: =C27/$B27 | D30: =D27/$B27 | E30: =E27/$B27 | F30: =F27/$B27 | G30: =G27/$B27 | H30: =H27/$B27 | I30: =I27/$B27 | ... Q30: =Q27/$B27
A32: F1 worst | B32: =HARMEAN(B26,B28) | C32: =HARMEAN(C26,C28) | D32: =HARMEAN(D26,D28) | E32: =HARMEAN(E26,E28) | F32: =HARMEAN(F26,F28) | G32: =HARMEAN(G26,G28) | H32: =HARMEAN(H26,H28) | I32: =HARMEAN(I26,I28) | ... Q32: =HARMEAN(Q26,Q28)
A33: F1 best | B33: =HARMEAN(B27,B28) | C33: =HARMEAN(C27,C28) | D33: =HARMEAN(D27,D28) | E33: =HARMEAN(E27,E28) | F33: =HARMEAN(F27,F28) | G33: =HARMEAN(G27,G28) | H33: =HARMEAN(H27,H28) | I33: =HARMEAN(I27,I28) | ... Q33: =HARMEAN(Q27,Q28)
A34: F2 worst | B34: =(1+2^2)*B28*B26/(2^2*B28+B26) | C34: =(1+2^2)*C28*C26/(2^2*C28+C26) | D34: =(1+2^2)*D28*D26/(2^2*D28+D26) | E34: =(1+2^2)*E28*E26/(2^2*E28+E26) | F34: =(1+2^2)*F28*F26/(2^2*F28+F26) | G34: =(1+2^2)*G28*G26/(2^2*G28+G26) | H34: =(1+2^2)*H28*H26/(2^2*H28+H26) | I34: =(1+2^2)*I28*I26/(2^2*I28+I26) | ... Q34: =(1+2^2)*Q28*Q26/(2^2*Q28+Q26)
A35: F2 best | B35: =(1+2^2)*B28*B27/(2^2*B28+B27) | C35: =(1+2^2)*C28*C27/(2^2*C28+C27) | D35: =(1+2^2)*D28*D27/(2^2*D28+D27) | E35: =(1+2^2)*E28*E27/(2^2*E28+E27) | F35: =(1+2^2)*F28*F27/(2^2*F28+F27) | G35: =(1+2^2)*G28*G27/(2^2*G28+G27) | H35: =(1+2^2)*H28*H27/(2^2*H28+H27) | I35: =(1+2^2)*I28*I27/(2^2*I28+I27) | ... Q35: =(1+2^2)*Q28*Q27/(2^2*Q28+Q27)
A36: F0.5 worst | B36: =(1+0.5^2)*B28*B26/(0.5^2*B28+B26) | C36: =(1+0.5^2)*C28*C26/(0.5^2*C28+C26) | D36: =(1+0.5^2)*D28*D26/(0.5^2*D28+D26) | E36: =(1+0.5^2)*E28*E26/(0.5^2*E28+E26) | F36: =(1+0.5^2)*F28*F26/(0.5^2*F28+F26) | G36: =(1+0.5^2)*G28*G26/(0.5^2*G28+G26) | H36: =(1+0.5^2)*H28*H26/(0.5^2*H28+H26) | I36: =(1+0.5^2)*I28*I26/(0.5^2*I28+I26) | ... Q36: =(1+0.5^2)*Q28*Q26/(0.5^2*Q28+Q26)
A37: F0.5 best | B37: =(1+0.5^2)*B28*B27/(0.5^2*B28+B27) | C37: =(1+0.5^2)*C28*C27/(0.5^2*C28+C27) | D37: =(1+0.5^2)*D28*D27/(0.5^2*D28+D27) | E37: =(1+0.5^2)*E28*E27/(0.5^2*E28+E27) | F37: =(1+0.5^2)*F28*F27/(0.5^2*F28+F27) | G37: =(1+0.5^2)*G28*G27/(0.5^2*G28+G27) | H37: =(1+0.5^2)*H28*H27/(0.5^2*H28+H27) | I37: =(1+0.5^2)*I28*I27/(0.5^2*I28+I27) | ... Q37: =(1+0.5^2)*Q28*Q27/(0.5^2*Q28+Q27)
A38: Relative F2 worst | B38: =(1+2^2)*B28*B29/(2^2*B28+B29) | C38: =(1+2^2)*C28*C29/(2^2*C28+C29) | D38: =(1+2^2)*D28*D29/(2^2*D28+D29) | E38: =(1+2^2)*E28*E29/(2^2*E28+E29) | F38: =(1+2^2)*F28*F29/(2^2*F28+F29) | G38: =(1+2^2)*G28*G29/(2^2*G28+G29) | H38: =(1+2^2)*H28*H29/(2^2*H28+H29) | I38: =(1+2^2)*I28*I29/(2^2*I28+I29) | ... Q38: =(1+2^2)*Q28*Q29/(2^2*Q28+Q29)
A39: Relative F2 best | B39: =(1+2^2)*B28*B30/(2^2*B28+B30) | C39: =(1+2^2)*C28*C30/(2^2*C28+C30) | D39: =(1+2^2)*D28*D30/(2^2*D28+D30) | E39: =(1+2^2)*E28*E30/(2^2*E28+E30) | F39: =(1+2^2)*F28*F30/(2^2*F28+F30) | G39: =(1+2^2)*G28*G30/(2^2*G28+G30) | H39: =(1+2^2)*H28*H30/(2^2*H28+H30) | I39: =(1+2^2)*I28*I30/(2^2*I28+I30) | ... Q39: =(1+2^2)*Q28*Q30/(2^2*Q28+Q30)
A41: P-value | B41: 0.1 | D41: (90%)
A42: Z | B42: =ABS(NORMSINV(B41/2))
A44: Recall worst [CI center] | C44: =(C26+$B$42^2/(2*C$17))/(1+($B$42^2/C$17)) | D44: =(D26+$B$42^2/(2*D$17))/(1+($B$42^2/D$17)) | E44: =(E26+$B$42^2/(2*E$17))/(1+($B$42^2/E$17)) | F44: =(F26+$B$42^2/(2*F$17))/(1+($B$42^2/F$17)) | G44: =(G26+$B$42^2/(2*G$17))/(1+($B$42^2/G$17)) | H44: =(H26+$B$42^2/(2*H$17))/(1+($B$42^2/H$17)) | I44: =(I26+$B$42^2/(2*I$17))/(1+($B$42^2/I$17)) | J44: =(J26+$B$42^2/(2*J$17))/(1+($B$42^2/J$17)) | ... Q44: =(Q26+$B$42^2/(2*Q$17))/(1+($B$42^2/Q$17))
A45: ± Margin of error | B45: ± | C45: =1/(1+$B$42^2/C$17)*$B$42*SQRT((C26*(1-C26)/C$17)+$B$42^2/(4*C$17^2)) | D45: =1/(1+$B$42^2/D$17)*$B$42*SQRT((D26*(1-D26)/D$17)+$B$42^2/(4*D$17^2)) | E45: =1/(1+$B$42^2/E$17)*$B$42*SQRT((E26*(1-E26)/E$17)+$B$42^2/(4*E$17^2)) | F45: =1/(1+$B$42^2/F$17)*$B$42*SQRT((F26*(1-F26)/F$17)+$B$42^2/(4*F$17^2)) | G45: =1/(1+$B$42^2/G$17)*$B$42*SQRT((G26*(1-G26)/G$17)+$B$42^2/(4*G$17^2)) | H45: =1/(1+$B$42^2/H$17)*$B$42*SQRT((H26*(1-H26)/H$17)+$B$42^2/(4*H$17^2)) | I45: =1/(1+$B$42^2/I$17)*$B$42*SQRT((I26*(1-I26)/I$17)+$B$42^2/(4*I$17^2)) | J45: =1/(1+$B$42^2/J$17)*$B$42*SQRT((J26*(1-J26)/J$17)+$B$42^2/(4*J$17^2)) | ... Q45: =1/(1+$B$42^2/Q$17)*$B$42*SQRT((Q26*(1-Q26)/Q$17)+$B$42^2/(4*Q$17^2))
A46: CI lower bound | C46: =C44-C45 | D46: =D44-D45 | E46: =E44-E45 | F46: =F44-F45 | G46: =G44-G45 | H46: =H44-H45 | I46: =I44-I45 | J46: =J44-J45 | ... Q46: =Q44-Q45
...

Sheet Summary {V}
A1: L0 | B1: Including hallucinations | E1: Excluding hallucinations
B2: Intersec. | C2: Union | D2: J-index | E2: Intersec. | F2: Union | G2: J-index
A3: L0_i vs L0_ii | B3: ='{V} L0'!H61 | C3: ='{V} L0'!I61 | D3: =B3/C3 | E3: ='{V} L0'!V61 | F3: ='{V} L0'!W61 | G3: =E3/F3
A4: L0_i vs L0_iii | B4: ='{V} L0'!J61 | C4: ='{V} L0'!K61 | D4: =B4/C4 | E4: ='{V} L0'!X61 | F4: ='{V} L0'!Y61 | G4: =E4/F4
A5: L0_i vs L0_iv | B5: ='{V} L0'!L61 | C5: ='{V} L0'!M61 | D5: =B5/C5 | E5: ='{V} L0'!Z61 | F5: ='{V} L0'!AA61 | G5: =E5/F5
A6: L0_ii vs L0_iii | B6: ='{V} L0'!N61 | C6: ='{V} L0'!O61 | D6: =B6/C6 | E6: ='{V} L0'!AB61 | F6: ='{V} L0'!AC61 | G6: =E6/F6
A7: L0_ii vs L0_iv | B7: ='{V} L0'!P61 | C7: ='{V} L0'!Q61 | D7: =B7/C7 | E7: ='{V} L0'!AD61 | F7: ='{V} L0'!AE61 | G7: =E7/F7
A8: L0_iii vs L0_iv | B8: ='{V} L0'!R61 | C8: ='{V} L0'!S61 | D8: =B8/C8 | E8: ='{V} L0'!AF61 | F8: ='{V} L0'!AG61 | G8: =E8/F8
A9: Mean (a) | D9: =AVERAGE(D3:D8) | G9: =AVERAGE(G3:G8)
A10: Mean (g) | D10: =GEOMEAN(D3:D8) | G10: =GEOMEAN(G3:G8)
A12: G0 | B12: Including hallucinations | E12: Excluding hallucinations
B13: Intersec. | C13: Union | D13: J-index | E13: Intersec. | F13: Union | G13: J-index
A14: G0_i vs G0_ii | B14: ='{V} G0'!H43 | C14: ='{V} G0'!I43 | D14: =B14/C14 | E14: ='{V} G0'!V43 | F14: ='{V} G0'!W43 | G14: =E14/F14
A15: G0_i vs G0_iii | B15: ='{V} G0'!J43 | C15: ='{V} G0'!K43 | D15: =B15/C15 | E15: ='{V} G0'!X43 | F15: ='{V} G0'!Y43 | G15: =E15/F15
A16: G0_i vs G0_iv | B16: ='{V} G0'!L43 | C16: ='{V} G0'!M43 | D16: =B16/C16 | E16: ='{V} G0'!Z43 | F16: ='{V} G0'!AA43 | G16: =E16/F16
A17: G0_ii vs G0_iii | B17: ='{V} G0'!N43 | C17: ='{V} G0'!O43 | D17: =B17/C17 | E17: ='{V} G0'!AB43 | F17: ='{V} G0'!AC43 | G17: =E17/F17
A18: G0_ii vs G0_iv | B18: ='{V} G0'!P43 | C18: ='{V} G0'!Q43 | D18: =B18/C18 | E18: ='{V} G0'!AD43 | F18: ='{V} G0'!AE43 | G18: =E18/F18
A19: G0_iii vs G0_iv | B19: ='{V} G0'!R43 | C19: ='{V} G0'!S43 | D19: =B19/C19 | E19: ='{V} G0'!AF43 | F19: ='{V} G0'!AG43 | G19: =E19/F19
A20: Mean (a) | D20: =AVERAGE(D14:D19) | G20: =AVERAGE(G14:G19)
A21: Mean (g) | D21: =GEOMEAN(D14:D19) | G21: =GEOMEAN(G14:G19)
A23: M0 | B23: Including hallucinations | E23: Excluding hallucinations
B24: Intersec. | C24: Union | D24: J-index | E24: Intersec. | F24: Union | G24: J-index
A25: M0_i vs M0_ii | B25: ='{V} M0'!H57 | C25: ='{V} M0'!I57 | D25: =B25/C25 | E25: ='{V} M0'!V57 | F25: ='{V} M0'!W57 | G25: =E25/F25
A26: M0_i vs M0_iii | B26: ='{V} M0'!J57 | C26: ='{V} M0'!K57 | D26: =B26/C26 | E26: ='{V} M0'!X57 | F26: ='{V} M0'!Y57 | G26: =E26/F26
A27: M0_i vs M0_iv | B27: ='{V} M0'!L57 | C27: ='{V} M0'!M57 | D27: =B27/C27 | E27: ='{V} M0'!Z57 | F27: ='{V} M0'!AA57 | G27: =E27/F27
A28: M0_ii vs M0_iii | B28: ='{V} M0'!N57 | C28: ='{V} M0'!O57 | D28: =B28/C28 | E28: ='{V} M0'!AB57 | F28: ='{V} M0'!AC57 | G28: =E28/F28
A29: M0_ii vs M0_iv | B29: ='{V} M0'!P57 | C29: ='{V} M0'!Q57 | D29: =B29/C29 | E29: ='{V} M0'!AD57 | F29: ='{V} M0'!AE57 | G29: =E29/F29
A30: M0_iii vs M0_iv | B30: ='{V} M0'!R57 | C30: ='{V} M0'!S57 | D30: =B30/C30 | E30: ='{V} M0'!AF57 | F30: ='{V} M0'!AG57 | G30: =E30/F30
A31: Mean (a) | D31: =AVERAGE(D25:D30) | G31: =AVERAGE(G25:G30)
A32: Mean (g) | D32: =GEOMEAN(D25:D30) | G32: =GEOMEAN(G25:G30)
A34: Q0 | B34: Including hallucinations | E34: Excluding hallucinations
B35: Intersec. | C35: Union | D35: J-index | E35: Intersec. | F35: Union | G35: J-index
A36: Q0_i vs Q0_ii | B36: ='{V} Q0'!H63 | C36: ='{V} Q0'!I63 | D36: =B36/C36 | E36: ='{V} Q0'!V63 | F36: ='{V} Q0'!W63 | G36: =E36/F36
A37: Q0_i vs Q0_iii | B37: ='{V} Q0'!J63 | C37: ='{V} Q0'!K63 | D37: =B37/C37 | E37: ='{V} Q0'!X63 | F37: ='{V} Q0'!Y63 | G37: =E37/F37
A38: Q0_i vs Q0_iv | B38: ='{V} Q0'!L63 | C38: ='{V} Q0'!M63 | D38: =B38/C38 | E38: ='{V} Q0'!Z63 | F38: ='{V} Q0'!AA63 | G38: =E38/F38
A39: Q0_ii vs Q0_iii | B39: ='{V} Q0'!N63 | C39: ='{V} Q0'!O63 | D39: =B39/C39 | E39: ='{V} Q0'!AB63 | F39: ='{V} Q0'!AC63 | G39: =E39/F39
A40: Q0_ii vs Q0_iv | B40: ='{V} Q0'!P63 | C40: ='{V} Q0'!Q63 | D40: =B40/C40 | E40: ='{V} Q0'!AD63 | F40: ='{V} Q0'!AE63 | G40: =E40/F40
A41: Q0_iii vs Q0_iv | B41: ='{V} Q0'!R63 | C41: ='{V} Q0'!S63 | D41: =B41/C41 | E41: ='{V} Q0'!AF63 | F41: ='{V} Q0'!AG63 | G41: =E41/F41
A42: Mean (a) | D42: =AVERAGE(D36:D41) | G42: =AVERAGE(G36:G41)
A43: Mean (g) | D43: =GEOMEAN(D36:D41) | G43: =GEOMEAN(G36:G41)
...

Sheet {V} L3
A1: # | B1: L3_i | C1: L3_ii | D1: L3_iii | E1: L3_iv | F1: Hall. | H1: L3_i && L3_ii | I1: L3_i || L3_ii | J1: L3_i && L3_iii | K1: L3_i || L3_iii | L1: L3_i && L3_iv | M1: L3_i || L3_iv | N1: L3_ii && L3_iii | O1: L3_ii || L3_iii | P1: L3_ii && L3_iv | Q1: L3_ii || L3_iv | R1: L3_iii && L3_iv | S1: L3_iii || L3_iv | V1: L3_i && L3_ii | W1: L3_i || L3_ii | X1: L3_i && L3_iii | Y1: L3_i || L3_iii | Z1: L3_i && L3_iv | AA1: L3_i || L3_iv | AB1: L3_ii && L3_iii | AC1: L3_ii || L3_iii | AD1: L3_ii && L3_iv | AE1: L3_ii || L3_iv | AF1: L3_iii && L3_iv | AG1: L3_iii || L3_iv
A2: H.1.1 | B2: X | C2: X | D2: X | E2: X | F2: No | H2: =AND(B2<>"",C2<>"") | I2: =OR(B2<>"",C2<>"") | J2: =AND(B2<>"",D2<>"") | K2: =OR(B2<>"",D2<>"") | L2: =AND(B2<>"",E2<>"") | M2: =OR(B2<>"",E2<>"") | N2: =AND(C2<>"",D2<>"") | O2: =OR(C2<>"",D2<>"") | P2: =AND(C2<>"",E2<>"") | Q2: =OR(C2<>"",E2<>"") | R2: =AND(D2<>"",E2<>"") | S2: =OR(D2<>"",E2<>"") | V2: =AND(B2<>"",C2<>"",F2="No") | W2: =AND(OR(B2<>"",C2<>""),F2="No") | X2: =AND(B2<>"",D2<>"",F2="No") | Y2: =AND(OR(B2<>"",D2<>""),F2="No") | Z2: =AND(B2<>"",E2<>"",F2="No") | AA2: =AND(OR(B2<>"",E2<>""),F2="No") | AB2: =AND(C2<>"",D2<>"",F2="No") | AC2: =AND(OR(C2<>"",D2<>""),F2="No") | AD2: =AND(C2<>"",E2<>"",F2="No") | AE2: =AND(OR(C2<>"",E2<>""),F2="No") | AF2: =AND(D2<>"",E2<>"",F2="No") | AG2: =AND(OR(D2<>"",E2<>""),F2="No")
A3: GS.1.3 | C3: X | E3: X | F3: No | H3: =AND(B3<>"",C3<>"") | I3: =OR(B3<>"",C3<>"") | J3: =AND(B3<>"",D3<>"") | K3: =OR(B3<>"",D3<>"") | L3: =AND(B3<>"",E3<>"") | M3: =OR(B3<>"",E3<>"") | N3: =AND(C3<>"",D3<>"") | O3: =OR(C3<>"",D3<>"") | P3: =AND(C3<>"",E3<>"") | Q3: =OR(C3<>"",E3<>"") | R3: =AND(D3<>"",E3<>"") | S3: =OR(D3<>"",E3<>"") | V3: =AND(B3<>"",C3<>"",F3="No") | W3: =AND(OR(B3<>"",C3<>""),F3="No") | X3: =AND(B3<>"",D3<>"",F3="No") | Y3: =AND(OR(B3<>"",D3<>""),F3="No") | Z3: =AND(B3<>"",E3<>"",F3="No") | AA3: =AND(OR(B3<>"",E3<>""),F3="No") | AB3: =AND(C3<>"",D3<>"",F3="No") | AC3: =AND(OR(C3<>"",D3<>""),F3="No") | AD3: =AND(C3<>"",E3<>"",F3="No") | AE3: =AND(OR(C3<>"",E3<>""),F3="No") | AF3: =AND(D3<>"",E3<>"",F3="No") | AG3: =AND(OR(D3<>"",E3<>""),F3="No")
A4: L3.1.2 | D4: X | F4: Yes | H4: =AND(B4<>"",C4<>"") | I4: =OR(B4<>"",C4<>"") | J4: =AND(B4<>"",D4<>"") | K4: =OR(B4<>"",D4<>"") | L4: =AND(B4<>"",E4<>"") | M4: =OR(B4<>"",E4<>"") | N4: =AND(C4<>"",D4<>"") | O4: =OR(C4<>"",D4<>"") | P4: =AND(C4<>"",E4<>"") | Q4: =OR(C4<>"",E4<>"") | R4: =AND(D4<>"",E4<>"") | S4: =OR(D4<>"",E4<>"") | V4: =AND(B4<>"",C4<>"",F4="No") | W4: =AND(OR(B4<>"",C4<>""),F4="No") | X4: =AND(B4<>"",D4<>"",F4="No") | Y4: =AND(OR(B4<>"",D4<>""),F4="No") | Z4: =AND(B4<>"",E4<>"",F4="No") | AA4: =AND(OR(B4<>"",E4<>""),F4="No") | AB4: =AND(C4<>"",D4<>"",F4="No") | AC4: =AND(OR(C4<>"",D4<>""),F4="No") | AD4: =AND(C4<>"",E4<>"",F4="No") | AE4: =AND(OR(C4<>"",E4<>""),F4="No") | AF4: =AND(D4<>"",E4<>"",F4="No") | AG4: =AND(OR(D4<>"",E4<>""),F4="No")
A5: L3.1.5 | C5: X | F5: Yes | H5: =AND(B5<>"",C5<>"") | I5: =OR(B5<>"",C5<>"") | J5: =AND(B5<>"",D5<>"") | K5: =OR(B5<>"",D5<>"") | L5: =AND(B5<>"",E5<>"") | M5: =OR(B5<>"",E5<>"") | N5: =AND(C5<>"",D5<>"") | O5: =OR(C5<>"",D5<>"") | P5: =AND(C5<>"",E5<>"") | Q5: =OR(C5<>"",E5<>"") | R5: =AND(D5<>"",E5<>"") | S5: =OR(D5<>"",E5<>"") | V5: =AND(B5<>"",C5<>"",F5="No") | W5: =AND(OR(B5<>"",C5<>""),F5="No") | X5: =AND(B5<>"",D5<>"",F5="No") | Y5: =AND(OR(B5<>"",D5<>""),F5="No") | Z5: =AND(B5<>"",E5<>"",F5="No") | AA5: =AND(OR(B5<>"",E5<>""),F5="No") | AB5: =AND(C5<>"",D5<>"",F5="No") | AC5: =AND(OR(C5<>"",D5<>""),F5="No") | AD5: =AND(C5<>"",E5<>"",F5="No") | AE5: =AND(OR(C5<>"",E5<>""),F5="No") | AF5: =AND(D5<>"",E5<>"",F5="No") | AG5: =AND(OR(D5<>"",E5<>""),F5="No")
A6: L3.1.6 | E6: X | F6: Yes | H6: =AND(B6<>"",C6<>"") | I6: =OR(B6<>"",C6<>"") | J6: =AND(B6<>"",D6<>"") | K6: =OR(B6<>"",D6<>"") | L6: =AND(B6<>"",E6<>"") | M6: =OR(B6<>"",E6<>"") | N6: =AND(C6<>"",D6<>"") | O6: =OR(C6<>"",D6<>"") | P6: =AND(C6<>"",E6<>"") | Q6: =OR(C6<>"",E6<>"") | R6: =AND(D6<>"",E6<>"") | S6: =OR(D6<>"",E6<>"") | V6: =AND(B6<>"",C6<>"",F6="No") | W6: =AND(OR(B6<>"",C6<>""),F6="No") | X6: =AND(B6<>"",D6<>"",F6="No") | Y6: =AND(OR(B6<>"",D6<>""),F6="No") | Z6: =AND(B6<>"",E6<>"",F6="No") | AA6: =AND(OR(B6<>"",E6<>""),F6="No") | AB6: =AND(C6<>"",D6<>"",F6="No") | AC6: =AND(OR(C6<>"",D6<>""),F6="No") | AD6: =AND(C6<>"",E6<>"",F6="No") | AE6: =AND(OR(C6<>"",E6<>""),F6="No") | AF6: =AND(D6<>"",E6<>"",F6="No") | AG6: =AND(OR(D6<>"",E6<>""),F6="No")
A7: H.2.1 | B7: X | C7: X | D7: X | E7: X | F7: No | H7: =AND(B7<>"",C7<>"") | I7: =OR(B7<>"",C7<>"") | J7: =AND(B7<>"",D7<>"") | K7: =OR(B7<>"",D7<>"") | L7: =AND(B7<>"",E7<>"") | M7: =OR(B7<>"",E7<>"") | N7: =AND(C7<>"",D7<>"") | O7: =OR(C7<>"",D7<>"") | P7: =AND(C7<>"",E7<>"") | Q7: =OR(C7<>"",E7<>"") | R7: =AND(D7<>"",E7<>"") | S7: =OR(D7<>"",E7<>"") | V7: =AND(B7<>"",C7<>"",F7="No") | W7: =AND(OR(B7<>"",C7<>""),F7="No") | X7: =AND(B7<>"",D7<>"",F7="No") | Y7: =AND(OR(B7<>"",D7<>""),F7="No") | Z7: =AND(B7<>"",E7<>"",F7="No") | AA7: =AND(OR(B7<>"",E7<>""),F7="No") | AB7: =AND(C7<>"",D7<>"",F7="No") | AC7: =AND(OR(C7<>"",D7<>""),F7="No") | AD7: =AND(C7<>"",E7<>"",F7="No") | AE7: =AND(OR(C7<>"",E7<>""),F7="No") | AF7: =AND(D7<>"",E7<>"",F7="No") | AG7: =AND(OR(D7<>"",E7<>""),F7="No")
A8: L3.2.4 | B8: X | F8: Yes | H8: =AND(B8<>"",C8<>"") | I8: =OR(B8<>"",C8<>"") | J8: =AND(B8<>"",D8<>"") | K8: =OR(B8<>"",D8<>"") | L8: =AND(B8<>"",E8<>"") | M8: =OR(B8<>"",E8<>"") | N8: =AND(C8<>"",D8<>"") | O8: =OR(C8<>"",D8<>"") | P8: =AND(C8<>"",E8<>"") | Q8: =OR(C8<>"",E8<>"") | R8: =AND(D8<>"",E8<>"") | S8: =OR(D8<>"",E8<>"") | V8: =AND(B8<>"",C8<>"",F8="No") | W8: =AND(OR(B8<>"",C8<>""),F8="No") | X8: =AND(B8<>"",D8<>"",F8="No") | Y8: =AND(OR(B8<>"",D8<>""),F8="No") | Z8: =AND(B8<>"",E8<>"",F8="No") | AA8: =AND(OR(B8<>"",E8<>""),F8="No") | AB8: =AND(C8<>"",D8<>"",F8="No") | AC8: =AND(OR(C8<>"",D8<>""),F8="No") | AD8: =AND(C8<>"",E8<>"",F8="No") | AE8: =AND(OR(C8<>"",E8<>""),F8="No") | AF8: =AND(D8<>"",E8<>"",F8="No") | AG8: =AND(OR(D8<>"",E8<>""),F8="No")
A9: L3.3.1 | B9: X | F9: Yes | H9: =AND(B9<>"",C9<>"") | I9: =OR(B9<>"",C9<>"") | J9: =AND(B9<>"",D9<>"") | K9: =OR(B9<>"",D9<>"") | L9: =AND(B9<>"",E9<>"") | M9: =OR(B9<>"",E9<>"") | N9: =AND(C9<>"",D9<>"") | O9: =OR(C9<>"",D9<>"") | P9: =AND(C9<>"",E9<>"") | Q9: =OR(C9<>"",E9<>"") | R9: =AND(D9<>"",E9<>"") | S9: =OR(D9<>"",E9<>"") | V9: =AND(B9<>"",C9<>"",F9="No") | W9: =AND(OR(B9<>"",C9<>""),F9="No") | X9: =AND(B9<>"",D9<>"",F9="No") | Y9: =AND(OR(B9<>"",D9<>""),F9="No") | Z9: =AND(B9<>"",E9<>"",F9="No") | AA9: =AND(OR(B9<>"",E9<>""),F9="No") | AB9: =AND(C9<>"",D9<>"",F9="No") | AC9: =AND(OR(C9<>"",D9<>""),F9="No") | AD9: =AND(C9<>"",E9<>"",F9="No") | AE9: =AND(OR(C9<>"",E9<>""),F9="No") | AF9: =AND(D9<>"",E9<>"",F9="No") | AG9: =AND(OR(D9<>"",E9<>""),F9="No")
A10: H.3.1 | B10: X | C10: X | D10: X | E10: X | F10: No | H10: =AND(B10<>"",C10<>"") | I10: =OR(B10<>"",C10<>"") | J10: =AND(B10<>"",D10<>"") | K10: =OR(B10<>"",D10<>"") | L10: =AND(B10<>"",E10<>"") | M10: =OR(B10<>"",E10<>"") | N10: =AND(C10<>"",D10<>"") | O10: =OR(C10<>"",D10<>"") | P10: =AND(C10<>"",E10<>"") | Q10: =OR(C10<>"",E10<>"") | R10: =AND(D10<>"",E10<>"") | S10: =OR(D10<>"",E10<>"") | V10: =AND(B10<>"",C10<>"",F10="No") | W10: =AND(OR(B10<>"",C10<>""),F10="No") | X10: =AND(B10<>"",D10<>"",F10="No") | Y10: =AND(OR(B10<>"",D10<>""),F10="No") | Z10: =AND(B10<>"",E10<>"",F10="No") | AA10: =AND(OR(B10<>"",E10<>""),F10="No") | AB10: =AND(C10<>"",D10<>"",F10="No") | AC10: =AND(OR(C10<>"",D10<>""),F10="No") | AD10: =AND(C10<>"",E10<>"",F10="No") | AE10: =AND(OR(C10<>"",E10<>""),F10="No") | AF10: =AND(D10<>"",E10<>"",F10="No") | AG10: =AND(OR(D10<>"",E10<>""),F10="No")
A11: H.3.2 | C11: X | F11: No | H11: =AND(B11<>"",C11<>"") | I11: =OR(B11<>"",C11<>"") | J11: =AND(B11<>"",D11<>"") | K11: =OR(B11<>"",D11<>"") | L11: =AND(B11<>"",E11<>"") | M11: =OR(B11<>"",E11<>"") | N11: =AND(C11<>"",D11<>"") | O11: =OR(C11<>"",D11<>"") | P11: =AND(C11<>"",E11<>"") | Q11: =OR(C11<>"",E11<>"") | R11: =AND(D11<>"",E11<>"") | S11: =OR(D11<>"",E11<>"") | V11: =AND(B11<>"",C11<>"",F11="No") | W11: =AND(OR(B11<>"",C11<>""),F11="No") | X11: =AND(B11<>"",D11<>"",F11="No") | Y11: =AND(OR(B11<>"",D11<>""),F11="No") | Z11: =AND(B11<>"",E11<>"",F11="No") | AA11: =AND(OR(B11<>"",E11<>""),F11="No") | AB11: =AND(C11<>"",D11<>"",F11="No") | AC11: =AND(OR(C11<>"",D11<>""),F11="No") | AD11: =AND(C11<>"",E11<>"",F11="No") | AE11: =AND(OR(C11<>"",E11<>""),F11="No") | AF11: =AND(D11<>"",E11<>"",F11="No") | AG11: =AND(OR(D11<>"",E11<>""),F11="No")
A12: H.3.4 | B12: X | C12: X | D12: X | E12: X | F12: No | H12: =AND(B12<>"",C12<>"") | I12: =OR(B12<>"",C12<>"") | J12: =AND(B12<>"",D12<>"") | K12: =OR(B12<>"",D12<>"") | L12: =AND(B12<>"",E12<>"") | M12: =OR(B12<>"",E12<>"") | N12: =AND(C12<>"",D12<>"") | O12: =OR(C12<>"",D12<>"") | P12: =AND(C12<>"",E12<>"") | Q12: =OR(C12<>"",E12<>"") | R12: =AND(D12<>"",E12<>"") | S12: =OR(D12<>"",E12<>"") | V12: =AND(B12<>"",C12<>"",F12="No") | W12: =AND(OR(B12<>"",C12<>""),F12="No") | X12: =AND(B12<>"",D12<>"",F12="No") | Y12: =AND(OR(B12<>"",D12<>""),F12="No") | Z12: =AND(B12<>"",E12<>"",F12="No") | AA12: =AND(OR(B12<>"",E12<>""),F12="No") | AB12: =AND(C12<>"",D12<>"",F12="No") | AC12: =AND(OR(C12<>"",D12<>""),F12="No") | AD12: =AND(C12<>"",E12<>"",F12="No") | AE12: =AND(OR(C12<>"",E12<>""),F12="No") | AF12: =AND(D12<>"",E12<>"",F12="No") | AG12: =AND(OR(D12<>"",E12<>""),F12="No")
A13: H.3.5 | C13: X | F13: No | H13: =AND(B13<>"",C13<>"") | I13: =OR(B13<>"",C13<>"") | J13: =AND(B13<>"",D13<>"") | K13: =OR(B13<>"",D13<>"") | L13: =AND(B13<>"",E13<>"") | M13: =OR(B13<>"",E13<>"") | N13: =AND(C13<>"",D13<>"") | O13: =OR(C13<>"",D13<>"") | P13: =AND(C13<>"",E13<>"") | Q13: =OR(C13<>"",E13<>"") | R13: =AND(D13<>"",E13<>"") | S13: =OR(D13<>"",E13<>"") | V13: =AND(B13<>"",C13<>"",F13="No") | W13: =AND(OR(B13<>"",C13<>""),F13="No") | X13: =AND(B13<>"",D13<>"",F13="No") | Y13: =AND(OR(B13<>"",D13<>""),F13="No") | Z13: =AND(B13<>"",E13<>"",F13="No") | AA13: =AND(OR(B13<>"",E13<>""),F13="No") | AB13: =AND(C13<>"",D13<>"",F13="No") | AC13: =AND(OR(C13<>"",D13<>""),F13="No") | AD13: =AND(C13<>"",E13<>"",F13="No") | AE13: =AND(OR(C13<>"",E13<>""),F13="No") | AF13: =AND(D13<>"",E13<>"",F13="No") | AG13: =AND(OR(D13<>"",E13<>""),F13="No")
A14: L3.3.3 | C14: X | E14: X | F14: Yes | H14: =AND(B14<>"",C14<>"") | I14: =OR(B14<>"",C14<>"") | J14: =AND(B14<>"",D14<>"") | K14: =OR(B14<>"",D14<>"") | L14: =AND(B14<>"",E14<>"") | M14: =OR(B14<>"",E14<>"") | N14: =AND(C14<>"",D14<>"") | O14: =OR(C14<>"",D14<>"") | P14: =AND(C14<>"",E14<>"") | Q14: =OR(C14<>"",E14<>"") | R14: =AND(D14<>"",E14<>"") | S14: =OR(D14<>"",E14<>"") | V14: =AND(B14<>"",C14<>"",F14="No") | W14: =AND(OR(B14<>"",C14<>""),F14="No") | X14: =AND(B14<>"",D14<>"",F14="No") | Y14: =AND(OR(B14<>"",D14<>""),F14="No") | Z14: =AND(B14<>"",E14<>"",F14="No") | AA14: =AND(OR(B14<>"",E14<>""),F14="No") | AB14: =AND(C14<>"",D14<>"",F14="No") | AC14: =AND(OR(C14<>"",D14<>""),F14="No") | AD14: =AND(C14<>"",E14<>"",F14="No") | AE14: =AND(OR(C14<>"",E14<>""),F14="No") | AF14: =AND(D14<>"",E14<>"",F14="No") | AG14: =AND(OR(D14<>"",E14<>""),F14="No")
A15: L3.3.4 | C15: X | D15: X | F15: Yes | H15: =AND(B15<>"",C15<>"") | I15: =OR(B15<>"",C15<>"") | J15: =AND(B15<>"",D15<>"") | K15: =OR(B15<>"",D15<>"") | L15: =AND(B15<>"",E15<>"") | M15: =OR(B15<>"",E15<>"") | N15: =AND(C15<>"",D15<>"") | O15: =OR(C15<>"",D15<>"") | P15: =AND(C15<>"",E15<>"") | Q15: =OR(C15<>"",E15<>"") | R15: =AND(D15<>"",E15<>"") | S15: =OR(D15<>"",E15<>"") | V15: =AND(B15<>"",C15<>"",F15="No") | W15: =AND(OR(B15<>"",C15<>""),F15="No") | X15: =AND(B15<>"",D15<>"",F15="No") | Y15: =AND(OR(B15<>"",D15<>""),F15="No") | Z15: =AND(B15<>"",E15<>"",F15="No") | AA15: =AND(OR(B15<>"",E15<>""),F15="No") | AB15: =AND(C15<>"",D15<>"",F15="No") | AC15: =AND(OR(C15<>"",D15<>""),F15="No") | AD15: =AND(C15<>"",E15<>"",F15="No") | AE15: =AND(OR(C15<>"",E15<>""),F15="No") | AF15: =AND(D15<>"",E15<>"",F15="No") | AG15: =AND(OR(D15<>"",E15<>""),F15="No")
A16: L3.3.8 | D16: X | F16: Yes | H16: =AND(B16<>"",C16<>"") | I16: =OR(B16<>"",C16<>"") | J16: =AND(B16<>"",D16<>"") | K16: =OR(B16<>"",D16<>"") | L16: =AND(B16<>"",E16<>"") | M16: =OR(B16<>"",E16<>"") | N16: =AND(C16<>"",D16<>"") | O16: =OR(C16<>"",D16<>"") | P16: =AND(C16<>"",E16<>"") | Q16: =OR(C16<>"",E16<>"") | R16: =AND(D16<>"",E16<>"") | S16: =OR(D16<>"",E16<>"") | V16: =AND(B16<>"",C16<>"",F16="No") | W16: =AND(OR(B16<>"",C16<>""),F16="No") | X16: =AND(B16<>"",D16<>"",F16="No") | Y16: =AND(OR(B16<>"",D16<>""),F16="No") | Z16: =AND(B16<>"",E16<>"",F16="No") | AA16: =AND(OR(B16<>"",E16<>""),F16="No") | AB16: =AND(C16<>"",D16<>"",F16="No") | AC16: =AND(OR(C16<>"",D16<>""),F16="No") | AD16: =AND(C16<>"",E16<>"",F16="No") | AE16: =AND(OR(C16<>"",E16<>""),F16="No") | AF16: =AND(D16<>"",E16<>"",F16="No") | AG16: =AND(OR(D16<>"",E16<>""),F16="No")
A17: L3.3.9 | B17: X | F17: Yes | H17: =AND(B17<>"",C17<>"") | I17: =OR(B17<>"",C17<>"") | J17: =AND(B17<>"",D17<>"") | K17: =OR(B17<>"",D17<>"") | L17: =AND(B17<>"",E17<>"") | M17: =OR(B17<>"",E17<>"") | N17: =AND(C17<>"",D17<>"") | O17: =OR(C17<>"",D17<>"") | P17: =AND(C17<>"",E17<>"") | Q17: =OR(C17<>"",E17<>"") | R17: =AND(D17<>"",E17<>"") | S17: =OR(D17<>"",E17<>"") | V17: =AND(B17<>"",C17<>"",F17="No") | W17: =AND(OR(B17<>"",C17<>""),F17="No") | X17: =AND(B17<>"",D17<>"",F17="No") | Y17: =AND(OR(B17<>"",D17<>""),F17="No") | Z17: =AND(B17<>"",E17<>"",F17="No") | AA17: =AND(OR(B17<>"",E17<>""),F17="No") | AB17: =AND(C17<>"",D17<>"",F17="No") | AC17: =AND(OR(C17<>"",D17<>""),F17="No") | AD17: =AND(C17<>"",E17<>"",F17="No") | AE17: =AND(OR(C17<>"",E17<>""),F17="No") | AF17: =AND(D17<>"",E17<>"",F17="No") | AG17: =AND(OR(D17<>"",E17<>""),F17="No")
A18: L3.3.10 | E18: X | F18: Yes | H18: =AND(B18<>"",C18<>"") | I18: =OR(B18<>"",C18<>"") | J18: =AND(B18<>"",D18<>"") | K18: =OR(B18<>"",D18<>"") | L18: =AND(B18<>"",E18<>"") | M18: =OR(B18<>"",E18<>"") | N18: =AND(C18<>"",D18<>"") | O18: =OR(C18<>"",D18<>"") | P18: =AND(C18<>"",E18<>"") | Q18: =OR(C18<>"",E18<>"") | R18: =AND(D18<>"",E18<>"") | S18: =OR(D18<>"",E18<>"") | V18: =AND(B18<>"",C18<>"",F18="No") | W18: =AND(OR(B18<>"",C18<>""),F18="No") | X18: =AND(B18<>"",D18<>"",F18="No") | Y18: =AND(OR(B18<>"",D18<>""),F18="No") | Z18: =AND(B18<>"",E18<>"",F18="No") | AA18: =AND(OR(B18<>"",E18<>""),F18="No") | AB18: =AND(C18<>"",D18<>"",F18="No") | AC18: =AND(OR(C18<>"",D18<>""),F18="No") | AD18: =AND(C18<>"",E18<>"",F18="No") | AE18: =AND(OR(C18<>"",E18<>""),F18="No") | AF18: =AND(D18<>"",E18<>"",F18="No") | AG18: =AND(OR(D18<>"",E18<>""),F18="No")
A19: L3.3.11 | D19: X | F19: Yes | H19: =AND(B19<>"",C19<>"") | I19: =OR(B19<>"",C19<>"") | J19: =AND(B19<>"",D19<>"") | K19: =OR(B19<>"",D19<>"") | L19: =AND(B19<>"",E19<>"") | M19: =OR(B19<>"",E19<>"") | N19: =AND(C19<>"",D19<>"") | O19: =OR(C19<>"",D19<>"") | P19: =AND(C19<>"",E19<>"") | Q19: =OR(C19<>"",E19<>"") | R19: =AND(D19<>"",E19<>"") | S19: =OR(D19<>"",E19<>"") | V19: =AND(B19<>"",C19<>"",F19="No") | W19: =AND(OR(B19<>"",C19<>""),F19="No") | X19: =AND(B19<>"",D19<>"",F19="No") | Y19: =AND(OR(B19<>"",D19<>""),F19="No") | Z19: =AND(B19<>"",E19<>"",F19="No") | AA19: =AND(OR(B19<>"",E19<>""),F19="No") | AB19: =AND(C19<>"",D19<>"",F19="No") | AC19: =AND(OR(C19<>"",D19<>""),F19="No") | AD19: =AND(C19<>"",E19<>"",F19="No") | AE19: =AND(OR(C19<>"",E19<>""),F19="No") | AF19: =AND(D19<>"",E19<>"",F19="No") | AG19: =AND(OR(D19<>"",E19<>""),F19="No")
A20: L3.3.12 | E20: X | F20: Yes | H20: =AND(B20<>"",C20<>"") | I20: =OR(B20<>"",C20<>"") | J20: =AND(B20<>"",D20<>"") | K20: =OR(B20<>"",D20<>"") | L20: =AND(B20<>"",E20<>"") | M20: =OR(B20<>"",E20<>"") | N20: =AND(C20<>"",D20<>"") | O20: =OR(C20<>"",D20<>"") | P20: =AND(C20<>"",E20<>"") | Q20: =OR(C20<>"",E20<>"") | R20: =AND(D20<>"",E20<>"") | S20: =OR(D20<>"",E20<>"") | V20: =AND(B20<>"",C20<>"",F20="No") | W20: =AND(OR(B20<>"",C20<>""),F20="No") | X20: =AND(B20<>"",D20<>"",F20="No") | Y20: =AND(OR(B20<>"",D20<>""),F20="No") | Z20: =AND(B20<>"",E20<>"",F20="No") | AA20: =AND(OR(B20<>"",E20<>""),F20="No") | AB20: =AND(C20<>"",D20<>"",F20="No") | AC20: =AND(OR(C20<>"",D20<>""),F20="No") | AD20: =AND(C20<>"",E20<>"",F20="No") | AE20: =AND(OR(C20<>"",E20<>""),F20="No") | AF20: =AND(D20<>"",E20<>"",F20="No") | AG20: =AND(OR(D20<>"",E20<>""),F20="No")
A21: L3.3.13 | E21: X | F21: Yes | H21: =AND(B21<>"",C21<>"") | I21: =OR(B21<>"",C21<>"") | J21: =AND(B21<>"",D21<>"") | K21: =OR(B21<>"",D21<>"") | L21: =AND(B21<>"",E21<>"") | M21: =OR(B21<>"",E21<>"") | N21: =AND(C21<>"",D21<>"") | O21: =OR(C21<>"",D21<>"") | P21: =AND(C21<>"",E21<>"") | Q21: =OR(C21<>"",E21<>"") | R21: =AND(D21<>"",E21<>"") | S21: =OR(D21<>"",E21<>"") | V21: =AND(B21<>"",C21<>"",F21="No") | W21: =AND(OR(B21<>"",C21<>""),F21="No") | X21: =AND(B21<>"",D21<>"",F21="No") | Y21: =AND(OR(B21<>"",D21<>""),F21="No") | Z21: =AND(B21<>"",E21<>"",F21="No") | AA21: =AND(OR(B21<>"",E21<>""),F21="No") | AB21: =AND(C21<>"",D21<>"",F21="No") | AC21: =AND(OR(C21<>"",D21<>""),F21="No") | AD21: =AND(C21<>"",E21<>"",F21="No") | AE21: =AND(OR(C21<>"",E21<>""),F21="No") | AF21: =AND(D21<>"",E21<>"",F21="No") | AG21: =AND(OR(D21<>"",E21<>""),F21="No")
A22: H.4.1 | B22: X | C22: X | D22: X | E22: X | F22: No | H22: =AND(B22<>"",C22<>"") | I22: =OR(B22<>"",C22<>"") | J22: =AND(B22<>"",D22<>"") | K22: =OR(B22<>"",D22<>"") | L22: =AND(B22<>"",E22<>"") | M22: =OR(B22<>"",E22<>"") | N22: =AND(C22<>"",D22<>"") | O22: =OR(C22<>"",D22<>"") | P22: =AND(C22<>"",E22<>"") | Q22: =OR(C22<>"",E22<>"") | R22: =AND(D22<>"",E22<>"") | S22: =OR(D22<>"",E22<>"") | V22: =AND(B22<>"",C22<>"",F22="No") | W22: =AND(OR(B22<>"",C22<>""),F22="No") | X22: =AND(B22<>"",D22<>"",F22="No") | Y22: =AND(OR(B22<>"",D22<>""),F22="No") | Z22: =AND(B22<>"",E22<>"",F22="No") | AA22: =AND(OR(B22<>"",E22<>""),F22="No") | AB22: =AND(C22<>"",D22<>"",F22="No") | AC22: =AND(OR(C22<>"",D22<>""),F22="No") | AD22: =AND(C22<>"",E22<>"",F22="No") | AE22: =AND(OR(C22<>"",E22<>""),F22="No") | AF22: =AND(D22<>"",E22<>"",F22="No") | AG22: =AND(OR(D22<>"",E22<>""),F22="No")
A23: H.4.2 | B23: X | C23: X | D23: X | E23: X | F23: No | H23: =AND(B23<>"",C23<>"") | I23: =OR(B23<>"",C23<>"") | J23: =AND(B23<>"",D23<>"") | K23: =OR(B23<>"",D23<>"") | L23: =AND(B23<>"",E23<>"") | M23: =OR(B23<>"",E23<>"") | N23: =AND(C23<>"",D23<>"") | O23: =OR(C23<>"",D23<>"") | P23: =AND(C23<>"",E23<>"") | Q23: =OR(C23<>"",E23<>"") | R23: =AND(D23<>"",E23<>"") | S23: =OR(D23<>"",E23<>"") | V23: =AND(B23<>"",C23<>"",F23="No") | W23: =AND(OR(B23<>"",C23<>""),F23="No") | X23: =AND(B23<>"",D23<>"",F23="No") | Y23: =AND(OR(B23<>"",D23<>""),F23="No") | Z23: =AND(B23<>"",E23<>"",F23="No") | AA23: =AND(OR(B23<>"",E23<>""),F23="No") | AB23: =AND(C23<>"",D23<>"",F23="No") | AC23: =AND(OR(C23<>"",D23<>""),F23="No") | AD23: =AND(C23<>"",E23<>"",F23="No") | AE23: =AND(OR(C23<>"",E23<>""),F23="No") | AF23: =AND(D23<>"",E23<>"",F23="No") | AG23: =AND(OR(D23<>"",E23<>""),F23="No")
A24: H.4.3 | B24: X | C24: X | D24: X | E24: X | F24: No | H24: =AND(B24<>"",C24<>"") | I24: =OR(B24<>"",C24<>"") | J24: =AND(B24<>"",D24<>"") | K24: =OR(B24<>"",D24<>"") | L24: =AND(B24<>"",E24<>"") | M24: =OR(B24<>"",E24<>"") | N24: =AND(C24<>"",D24<>"") | O24: =OR(C24<>"",D24<>"") | P24: =AND(C24<>"",E24<>"") | Q24: =OR(C24<>"",E24<>"") | R24: =AND(D24<>"",E24<>"") | S24: =OR(D24<>"",E24<>"") | V24: =AND(B24<>"",C24<>"",F24="No") | W24: =AND(OR(B24<>"",C24<>""),F24="No") | X24: =AND(B24<>"",D24<>"",F24="No") | Y24: =AND(OR(B24<>"",D24<>""),F24="No") | Z24: =AND(B24<>"",E24<>"",F24="No") | AA24: =AND(OR(B24<>"",E24<>""),F24="No") | AB24: =AND(C24<>"",D24<>"",F24="No") | AC24: =AND(OR(C24<>"",D24<>""),F24="No") | AD24: =AND(C24<>"",E24<>"",F24="No") | AE24: =AND(OR(C24<>"",E24<>""),F24="No") | AF24: =AND(D24<>"",E24<>"",F24="No") | AG24: =AND(OR(D24<>"",E24<>""),F24="No")
A25: H.4.4 | E25: X | F25: No | H25: =AND(B25<>"",C25<>"") | I25: =OR(B25<>"",C25<>"") | J25: =AND(B25<>"",D25<>"") | K25: =OR(B25<>"",D25<>"") | L25: =AND(B25<>"",E25<>"") | M25: =OR(B25<>"",E25<>"") | N25: =AND(C25<>"",D25<>"") | O25: =OR(C25<>"",D25<>"") | P25: =AND(C25<>"",E25<>"") | Q25: =OR(C25<>"",E25<>"") | R25: =AND(D25<>"",E25<>"") | S25: =OR(D25<>"",E25<>"") | V25: =AND(B25<>"",C25<>"",F25="No") | W25: =AND(OR(B25<>"",C25<>""),F25="No") | X25: =AND(B25<>"",D25<>"",F25="No") | Y25: =AND(OR(B25<>"",D25<>""),F25="No") | Z25: =AND(B25<>"",E25<>"",F25="No") | AA25: =AND(OR(B25<>"",E25<>""),F25="No") | AB25: =AND(C25<>"",D25<>"",F25="No") | AC25: =AND(OR(C25<>"",D25<>""),F25="No") | AD25: =AND(C25<>"",E25<>"",F25="No") | AE25: =AND(OR(C25<>"",E25<>""),F25="No") | AF25: =AND(D25<>"",E25<>"",F25="No") | AG25: =AND(OR(D25<>"",E25<>""),F25="No")
A26: H.4.5 | B26: X | C26: X | D26: X | E26: X | F26: No | H26: =AND(B26<>"",C26<>"") | I26: =OR(B26<>"",C26<>"") | J26: =AND(B26<>"",D26<>"") | K26: =OR(B26<>"",D26<>"") | L26: =AND(B26<>"",E26<>"") | M26: =OR(B26<>"",E26<>"") | N26: =AND(C26<>"",D26<>"") | O26: =OR(C26<>"",D26<>"") | P26: =AND(C26<>"",E26<>"") | Q26: =OR(C26<>"",E26<>"") | R26: =AND(D26<>"",E26<>"") | S26: =OR(D26<>"",E26<>"") | V26: =AND(B26<>"",C26<>"",F26="No") | W26: =AND(OR(B26<>"",C26<>""),F26="No") | X26: =AND(B26<>"",D26<>"",F26="No") | Y26: =AND(OR(B26<>"",D26<>""),F26="No") | Z26: =AND(B26<>"",E26<>"",F26="No") | AA26: =AND(OR(B26<>"",E26<>""),F26="No") | AB26: =AND(C26<>"",D26<>"",F26="No") | AC26: =AND(OR(C26<>"",D26<>""),F26="No") | AD26: =AND(C26<>"",E26<>"",F26="No") | AE26: =AND(OR(C26<>"",E26<>""),F26="No") | AF26: =AND(D26<>"",E26<>"",F26="No") | AG26: =AND(OR(D26<>"",E26<>""),F26="No")
A27: H.4.7 | E27: P | F27: No | H27: =AND(B27<>"",C27<>"") | I27: =OR(B27<>"",C27<>"") | J27: =AND(B27<>"",D27<>"") | K27: =OR(B27<>"",D27<>"") | L27: =AND(B27<>"",E27<>"") | M27: =OR(B27<>"",E27<>"") | N27: =AND(C27<>"",D27<>"") | O27: =OR(C27<>"",D27<>"") | P27: =AND(C27<>"",E27<>"") | Q27: =OR(C27<>"",E27<>"") | R27: =AND(D27<>"",E27<>"") | S27: =OR(D27<>"",E27<>"") | V27: =AND(B27<>"",C27<>"",F27="No") | W27: =AND(OR(B27<>"",C27<>""),F27="No") | X27: =AND(B27<>"",D27<>"",F27="No") | Y27: =AND(OR(B27<>"",D27<>""),F27="No") | Z27: =AND(B27<>"",E27<>"",F27="No") | AA27: =AND(OR(B27<>"",E27<>""),F27="No") | AB27: =AND(C27<>"",D27<>"",F27="No") | AC27: =AND(OR(C27<>"",D27<>""),F27="No") | AD27: =AND(C27<>"",E27<>"",F27="No") | AE27: =AND(OR(C27<>"",E27<>""),F27="No") | AF27: =AND(D27<>"",E27<>"",F27="No") | AG27: =AND(OR(D27<>"",E27<>""),F27="No")
A28: H.4.8 | C28: X | D28: X | E28: X | F28: No | H28: =AND(B28<>"",C28<>"") | I28: =OR(B28<>"",C28<>"") | J28: =AND(B28<>"",D28<>"") | K28: =OR(B28<>"",D28<>"") | L28: =AND(B28<>"",E28<>"") | M28: =OR(B28<>"",E28<>"") | N28: =AND(C28<>"",D28<>"") | O28: =OR(C28<>"",D28<>"") | P28: =AND(C28<>"",E28<>"") | Q28: =OR(C28<>"",E28<>"") | R28: =AND(D28<>"",E28<>"") | S28: =OR(D28<>"",E28<>"") | V28: =AND(B28<>"",C28<>"",F28="No") | W28: =AND(OR(B28<>"",C28<>""),F28="No") | X28: =AND(B28<>"",D28<>"",F28="No") | Y28: =AND(OR(B28<>"",D28<>""),F28="No") | Z28: =AND(B28<>"",E28<>"",F28="No") | AA28: =AND(OR(B28<>"",E28<>""),F28="No") | AB28: =AND(C28<>"",D28<>"",F28="No") | AC28: =AND(OR(C28<>"",D28<>""),F28="No") | AD28: =AND(C28<>"",E28<>"",F28="No") | AE28: =AND(OR(C28<>"",E28<>""),F28="No") | AF28: =AND(D28<>"",E28<>"",F28="No") | AG28: =AND(OR(D28<>"",E28<>""),F28="No")
A29: GS.4.10 | B29: X | C29: X | F29: No | H29: =AND(B29<>"",C29<>"") | I29: =OR(B29<>"",C29<>"") | J29: =AND(B29<>"",D29<>"") | K29: =OR(B29<>"",D29<>"") | L29: =AND(B29<>"",E29<>"") | M29: =OR(B29<>"",E29<>"") | N29: =AND(C29<>"",D29<>"") | O29: =OR(C29<>"",D29<>"") | P29: =AND(C29<>"",E29<>"") | Q29: =OR(C29<>"",E29<>"") | R29: =AND(D29<>"",E29<>"") | S29: =OR(D29<>"",E29<>"") | V29: =AND(B29<>"",C29<>"",F29="No") | W29: =AND(OR(B29<>"",C29<>""),F29="No") | X29: =AND(B29<>"",D29<>"",F29="No") | Y29: =AND(OR(B29<>"",D29<>""),F29="No") | Z29: =AND(B29<>"",E29<>"",F29="No") | AA29: =AND(OR(B29<>"",E29<>""),F29="No") | AB29: =AND(C29<>"",D29<>"",F29="No") | AC29: =AND(OR(C29<>"",D29<>""),F29="No") | AD29: =AND(C29<>"",E29<>"",F29="No") | AE29: =AND(OR(C29<>"",E29<>""),F29="No") | AF29: =AND(D29<>"",E29<>"",F29="No") | AG29: =AND(OR(D29<>"",E29<>""),F29="No")
A30: GS.4.14 | B30: X | C30: X | D30: X | E30: X | F30: No | H30: =AND(B30<>"",C30<>"") | I30: =OR(B30<>"",C30<>"") | J30: =AND(B30<>"",D30<>"") | K30: =OR(B30<>"",D30<>"") | L30: =AND(B30<>"",E30<>"") | M30: =OR(B30<>"",E30<>"") | N30: =AND(C30<>"",D30<>"") | O30: =OR(C30<>"",D30<>"") | P30: =AND(C30<>"",E30<>"") | Q30: =OR(C30<>"",E30<>"") | R30: =AND(D30<>"",E30<>"") | S30: =OR(D30<>"",E30<>"") | V30: =AND(B30<>"",C30<>"",F30="No") | W30: =AND(OR(B30<>"",C30<>""),F30="No") | X30: =AND(B30<>"",D30<>"",F30="No") | Y30: =AND(OR(B30<>"",D30<>""),F30="No") | Z30: =AND(B30<>"",E30<>"",F30="No") | AA30: =AND(OR(B30<>"",E30<>""),F30="No") | AB30: =AND(C30<>"",D30<>"",F30="No") | AC30: =AND(OR(C30<>"",D30<>""),F30="No") | AD30: =AND(C30<>"",E30<>"",F30="No") | AE30: =AND(OR(C30<>"",E30<>""),F30="No") | AF30: =AND(D30<>"",E30<>"",F30="No") | AG30: =AND(OR(D30<>"",E30<>""),F30="No")
A31: GS.4.20 | B31: X | C31: X | D31: X | E31: X | F31: No | H31: =AND(B31<>"",C31<>"") | I31: =OR(B31<>"",C31<>"") | J31: =AND(B31<>"",D31<>"") | K31: =OR(B31<>"",D31<>"") | L31: =AND(B31<>"",E31<>"") | M31: =OR(B31<>"",E31<>"") | N31: =AND(C31<>"",D31<>"") | O31: =OR(C31<>"",D31<>"") | P31: =AND(C31<>"",E31<>"") | Q31: =OR(C31<>"",E31<>"") | R31: =AND(D31<>"",E31<>"") | S31: =OR(D31<>"",E31<>"") | V31: =AND(B31<>"",C31<>"",F31="No") | W31: =AND(OR(B31<>"",C31<>""),F31="No") | X31: =AND(B31<>"",D31<>"",F31="No") | Y31: =AND(OR(B31<>"",D31<>""),F31="No") | Z31: =AND(B31<>"",E31<>"",F31="No") | AA31: =AND(OR(B31<>"",E31<>""),F31="No") | AB31: =AND(C31<>"",D31<>"",F31="No") | AC31: =AND(OR(C31<>"",D31<>""),F31="No") | AD31: =AND(C31<>"",E31<>"",F31="No") | AE31: =AND(OR(C31<>"",E31<>""),F31="No") | AF31: =AND(D31<>"",E31<>"",F31="No") | AG31: =AND(OR(D31<>"",E31<>""),F31="No")
A32: GS.4.21 | E32: X | F32: No | H32: =AND(B32<>"",C32<>"") | I32: =OR(B32<>"",C32<>"") | J32: =AND(B32<>"",D32<>"") | K32: =OR(B32<>"",D32<>"") | L32: =AND(B32<>"",E32<>"") | M32: =OR(B32<>"",E32<>"") | N32: =AND(C32<>"",D32<>"") | O32: =OR(C32<>"",D32<>"") | P32: =AND(C32<>"",E32<>"") | Q32: =OR(C32<>"",E32<>"") | R32: =AND(D32<>"",E32<>"") | S32: =OR(D32<>"",E32<>"") | V32: =AND(B32<>"",C32<>"",F32="No") | W32: =AND(OR(B32<>"",C32<>""),F32="No") | X32: =AND(B32<>"",D32<>"",F32="No") | Y32: =AND(OR(B32<>"",D32<>""),F32="No") | Z32: =AND(B32<>"",E32<>"",F32="No") | AA32: =AND(OR(B32<>"",E32<>""),F32="No") | AB32: =AND(C32<>"",D32<>"",F32="No") | AC32: =AND(OR(C32<>"",D32<>""),F32="No") | AD32: =AND(C32<>"",E32<>"",F32="No") | AE32: =AND(OR(C32<>"",E32<>""),F32="No") | AF32: =AND(D32<>"",E32<>"",F32="No") | AG32: =AND(OR(D32<>"",E32<>""),F32="No")
A33: H.5.1 | B33: X | C33: X | D33: X | E33: X | F33: No | H33: =AND(B33<>"",C33<>"") | I33: =OR(B33<>"",C33<>"") | J33: =AND(B33<>"",D33<>"") | K33: =OR(B33<>"",D33<>"") | L33: =AND(B33<>"",E33<>"") | M33: =OR(B33<>"",E33<>"") | N33: =AND(C33<>"",D33<>"") | O33: =OR(C33<>"",D33<>"") | P33: =AND(C33<>"",E33<>"") | Q33: =OR(C33<>"",E33<>"") | R33: =AND(D33<>"",E33<>"") | S33: =OR(D33<>"",E33<>"") | V33: =AND(B33<>"",C33<>"",F33="No") | W33: =AND(OR(B33<>"",C33<>""),F33="No") | X33: =AND(B33<>"",D33<>"",F33="No") | Y33: =AND(OR(B33<>"",D33<>""),F33="No") | Z33: =AND(B33<>"",E33<>"",F33="No") | AA33: =AND(OR(B33<>"",E33<>""),F33="No") | AB33: =AND(C33<>"",D33<>"",F33="No") | AC33: =AND(OR(C33<>"",D33<>""),F33="No") | AD33: =AND(C33<>"",E33<>"",F33="No") | AE33: =AND(OR(C33<>"",E33<>""),F33="No") | AF33: =AND(D33<>"",E33<>"",F33="No") | AG33: =AND(OR(D33<>"",E33<>""),F33="No")
A34: GS.5.3 | B34: X | D34: X | F34: No | H34: =AND(B34<>"",C34<>"") | I34: =OR(B34<>"",C34<>"") | J34: =AND(B34<>"",D34<>"") | K34: =OR(B34<>"",D34<>"") | L34: =AND(B34<>"",E34<>"") | M34: =OR(B34<>"",E34<>"") | N34: =AND(C34<>"",D34<>"") | O34: =OR(C34<>"",D34<>"") | P34: =AND(C34<>"",E34<>"") | Q34: =OR(C34<>"",E34<>"") | R34: =AND(D34<>"",E34<>"") | S34: =OR(D34<>"",E34<>"") | V34: =AND(B34<>"",C34<>"",F34="No") | W34: =AND(OR(B34<>"",C34<>""),F34="No") | X34: =AND(B34<>"",D34<>"",F34="No") | Y34: =AND(OR(B34<>"",D34<>""),F34="No") | Z34: =AND(B34<>"",E34<>"",F34="No") | AA34: =AND(OR(B34<>"",E34<>""),F34="No") | AB34: =AND(C34<>"",D34<>"",F34="No") | AC34: =AND(OR(C34<>"",D34<>""),F34="No") | AD34: =AND(C34<>"",E34<>"",F34="No") | AE34: =AND(OR(C34<>"",E34<>""),F34="No") | AF34: =AND(D34<>"",E34<>"",F34="No") | AG34: =AND(OR(D34<>"",E34<>""),F34="No")
A35: GS.5.5 | B35: X | F35: No | H35: =AND(B35<>"",C35<>"") | I35: =OR(B35<>"",C35<>"") | J35: =AND(B35<>"",D35<>"") | K35: =OR(B35<>"",D35<>"") | L35: =AND(B35<>"",E35<>"") | M35: =OR(B35<>"",E35<>"") | N35: =AND(C35<>"",D35<>"") | O35: =OR(C35<>"",D35<>"") | P35: =AND(C35<>"",E35<>"") | Q35: =OR(C35<>"",E35<>"") | R35: =AND(D35<>"",E35<>"") | S35: =OR(D35<>"",E35<>"") | V35: =AND(B35<>"",C35<>"",F35="No") | W35: =AND(OR(B35<>"",C35<>""),F35="No") | X35: =AND(B35<>"",D35<>"",F35="No") | Y35: =AND(OR(B35<>"",D35<>""),F35="No") | Z35: =AND(B35<>"",E35<>"",F35="No") | AA35: =AND(OR(B35<>"",E35<>""),F35="No") | AB35: =AND(C35<>"",D35<>"",F35="No") | AC35: =AND(OR(C35<>"",D35<>""),F35="No") | AD35: =AND(C35<>"",E35<>"",F35="No") | AE35: =AND(OR(C35<>"",E35<>""),F35="No") | AF35: =AND(D35<>"",E35<>"",F35="No") | AG35: =AND(OR(D35<>"",E35<>""),F35="No")
A36: L3.5.6 | D36: X | F36: Yes | H36: =AND(B36<>"",C36<>"") | I36: =OR(B36<>"",C36<>"") | J36: =AND(B36<>"",D36<>"") | K36: =OR(B36<>"",D36<>"") | L36: =AND(B36<>"",E36<>"") | M36: =OR(B36<>"",E36<>"") | N36: =AND(C36<>"",D36<>"") | O36: =OR(C36<>"",D36<>"") | P36: =AND(C36<>"",E36<>"") | Q36: =OR(C36<>"",E36<>"") | R36: =AND(D36<>"",E36<>"") | S36: =OR(D36<>"",E36<>"") | V36: =AND(B36<>"",C36<>"",F36="No") | W36: =AND(OR(B36<>"",C36<>""),F36="No") | X36: =AND(B36<>"",D36<>"",F36="No") | Y36: =AND(OR(B36<>"",D36<>""),F36="No") | Z36: =AND(B36<>"",E36<>"",F36="No") | AA36: =AND(OR(B36<>"",E36<>""),F36="No") | AB36: =AND(C36<>"",D36<>"",F36="No") | AC36: =AND(OR(C36<>"",D36<>""),F36="No") | AD36: =AND(C36<>"",E36<>"",F36="No") | AE36: =AND(OR(C36<>"",E36<>""),F36="No") | AF36: =AND(D36<>"",E36<>"",F36="No") | AG36: =AND(OR(D36<>"",E36<>""),F36="No")
A37: L3.5.7 | D37: X | F37: Yes | H37: =AND(B37<>"",C37<>"") | I37: =OR(B37<>"",C37<>"") | J37: =AND(B37<>"",D37<>"") | K37: =OR(B37<>"",D37<>"") | L37: =AND(B37<>"",E37<>"") | M37: =OR(B37<>"",E37<>"") | N37: =AND(C37<>"",D37<>"") | O37: =OR(C37<>"",D37<>"") | P37: =AND(C37<>"",E37<>"") | Q37: =OR(C37<>"",E37<>"") | R37: =AND(D37<>"",E37<>"") | S37: =OR(D37<>"",E37<>"") | V37: =AND(B37<>"",C37<>"",F37="No") | W37: =AND(OR(B37<>"",C37<>""),F37="No") | X37: =AND(B37<>"",D37<>"",F37="No") | Y37: =AND(OR(B37<>"",D37<>""),F37="No") | Z37: =AND(B37<>"",E37<>"",F37="No") | AA37: =AND(OR(B37<>"",E37<>""),F37="No") | AB37: =AND(C37<>"",D37<>"",F37="No") | AC37: =AND(OR(C37<>"",D37<>""),F37="No") | AD37: =AND(C37<>"",E37<>"",F37="No") | AE37: =AND(OR(C37<>"",E37<>""),F37="No") | AF37: =AND(D37<>"",E37<>"",F37="No") | AG37: =AND(OR(D37<>"",E37<>""),F37="No")
A38: H.6.1 | B38: X | C38: X | D38: X | E38: X | F38: No | H38: =AND(B38<>"",C38<>"") | I38: =OR(B38<>"",C38<>"") | J38: =AND(B38<>"",D38<>"") | K38: =OR(B38<>"",D38<>"") | L38: =AND(B38<>"",E38<>"") | M38: =OR(B38<>"",E38<>"") | N38: =AND(C38<>"",D38<>"") | O38: =OR(C38<>"",D38<>"") | P38: =AND(C38<>"",E38<>"") | Q38: =OR(C38<>"",E38<>"") | R38: =AND(D38<>"",E38<>"") | S38: =OR(D38<>"",E38<>"") | V38: =AND(B38<>"",C38<>"",F38="No") | W38: =AND(OR(B38<>"",C38<>""),F38="No") | X38: =AND(B38<>"",D38<>"",F38="No") | Y38: =AND(OR(B38<>"",D38<>""),F38="No") | Z38: =AND(B38<>"",E38<>"",F38="No") | AA38: =AND(OR(B38<>"",E38<>""),F38="No") | AB38: =AND(C38<>"",D38<>"",F38="No") | AC38: =AND(OR(C38<>"",D38<>""),F38="No") | AD38: =AND(C38<>"",E38<>"",F38="No") | AE38: =AND(OR(C38<>"",E38<>""),F38="No") | AF38: =AND(D38<>"",E38<>"",F38="No") | AG38: =AND(OR(D38<>"",E38<>""),F38="No")
A39: GS.6.4 | E39: X | F39: No | H39: =AND(B39<>"",C39<>"") | I39: =OR(B39<>"",C39<>"") | J39: =AND(B39<>"",D39<>"") | K39: =OR(B39<>"",D39<>"") | L39: =AND(B39<>"",E39<>"") | M39: =OR(B39<>"",E39<>"") | N39: =AND(C39<>"",D39<>"") | O39: =OR(C39<>"",D39<>"") | P39: =AND(C39<>"",E39<>"") | Q39: =OR(C39<>"",E39<>"") | R39: =AND(D39<>"",E39<>"") | S39: =OR(D39<>"",E39<>"") | V39: =AND(B39<>"",C39<>"",F39="No") | W39: =AND(OR(B39<>"",C39<>""),F39="No") | X39: =AND(B39<>"",D39<>"",F39="No") | Y39: =AND(OR(B39<>"",D39<>""),F39="No") | Z39: =AND(B39<>"",E39<>"",F39="No") | AA39: =AND(OR(B39<>"",E39<>""),F39="No") | AB39: =AND(C39<>"",D39<>"",F39="No") | AC39: =AND(OR(C39<>"",D39<>""),F39="No") | AD39: =AND(C39<>"",E39<>"",F39="No") | AE39: =AND(OR(C39<>"",E39<>""),F39="No") | AF39: =AND(D39<>"",E39<>"",F39="No") | AG39: =AND(OR(D39<>"",E39<>""),F39="No")
A40: H.7.1 | B40: X | C40: X | D40: X | E40: X | F40: No | H40: =AND(B40<>"",C40<>"") | I40: =OR(B40<>"",C40<>"") | J40: =AND(B40<>"",D40<>"") | K40: =OR(B40<>"",D40<>"") | L40: =AND(B40<>"",E40<>"") | M40: =OR(B40<>"",E40<>"") | N40: =AND(C40<>"",D40<>"") | O40: =OR(C40<>"",D40<>"") | P40: =AND(C40<>"",E40<>"") | Q40: =OR(C40<>"",E40<>"") | R40: =AND(D40<>"",E40<>"") | S40: =OR(D40<>"",E40<>"") | V40: =AND(B40<>"",C40<>"",F40="No") | W40: =AND(OR(B40<>"",C40<>""),F40="No") | X40: =AND(B40<>"",D40<>"",F40="No") | Y40: =AND(OR(B40<>"",D40<>""),F40="No") | Z40: =AND(B40<>"",E40<>"",F40="No") | AA40: =AND(OR(B40<>"",E40<>""),F40="No") | AB40: =AND(C40<>"",D40<>"",F40="No") | AC40: =AND(OR(C40<>"",D40<>""),F40="No") | AD40: =AND(C40<>"",E40<>"",F40="No") | AE40: =AND(OR(C40<>"",E40<>""),F40="No") | AF40: =AND(D40<>"",E40<>"",F40="No") | AG40: =AND(OR(D40<>"",E40<>""),F40="No")
...

Sheet {V} L0
A1: # | B1: L0_i | C1: L0_ii | D1: L0_iii | E1: L0_iv | F1: Hall. | H1: L0_i && L0_ii | I1: L0_i || L0_ii | J1: L0_i && L0_iii | K1: L0_i || L0_iii | L1: L0_i && L0_iv | M1: L0_i || L0_iv | N1: L0_ii && L0_iii | O1: L0_ii || L0_iii | P1: L0_ii && L0_iv | Q1: L0_ii || L0_iv | R1: L0_iii && L0_iv | S1: L0_iii || L0_iv | V1: L0_i && L0_ii | W1: L0_i || L0_ii | X1: L0_i && L0_iii | Y1: L0_i || L0_iii | Z1: L0_i && L0_iv | AA1: L0_i || L0_iv | AB1: L0_ii && L0_iii | AC1: L0_ii || L0_iii | AD1: L0_ii && L0_iv | AE1: L0_ii || L0_iv | AF1: L0_iii && L0_iv | AG1: L0_iii || L0_iv
A2: H.1.1 | B2: X | C2: X | D2: X | E2: X | F2: No | H2: =AND(B2<>"",C2<>"") | I2: =OR(B2<>"",C2<>"") | J2: =AND(B2<>"",D2<>"") | K2: =OR(B2<>"",D2<>"") | L2: =AND(B2<>"",E2<>"") | M2: =OR(B2<>"",E2<>"") | N2: =AND(C2<>"",D2<>"") | O2: =OR(C2<>"",D2<>"") | P2: =AND(C2<>"",E2<>"") | Q2: =OR(C2<>"",E2<>"") | R2: =AND(D2<>"",E2<>"") | S2: =OR(D2<>"",E2<>"") | V2: =AND(B2<>"",C2<>"",F2="No") | W2: =AND(OR(B2<>"",C2<>""),F2="No") | X2: =AND(B2<>"",D2<>"",F2="No") | Y2: =AND(OR(B2<>"",D2<>""),F2="No") | Z2: =AND(B2<>"",E2<>"",F2="No") | AA2: =AND(OR(B2<>"",E2<>""),F2="No") | AB2: =AND(C2<>"",D2<>"",F2="No") | AC2: =AND(OR(C2<>"",D2<>""),F2="No") | AD2: =AND(C2<>"",E2<>"",F2="No") | AE2: =AND(OR(C2<>"",E2<>""),F2="No") | AF2: =AND(D2<>"",E2<>"",F2="No") | AG2: =AND(OR(D2<>"",E2<>""),F2="No")
A3: H.2.1 | B3: X | C3: X | D3: X | E3: X | F3: No | H3: =AND(B3<>"",C3<>"") | I3: =OR(B3<>"",C3<>"") | J3: =AND(B3<>"",D3<>"") | K3: =OR(B3<>"",D3<>"") | L3: =AND(B3<>"",E3<>"") | M3: =OR(B3<>"",E3<>"") | N3: =AND(C3<>"",D3<>"") | O3: =OR(C3<>"",D3<>"") | P3: =AND(C3<>"",E3<>"") | Q3: =OR(C3<>"",E3<>"") | R3: =AND(D3<>"",E3<>"") | S3: =OR(D3<>"",E3<>"") | V3: =AND(B3<>"",C3<>"",F3="No") | W3: =AND(OR(B3<>"",C3<>""),F3="No") | X3: =AND(B3<>"",D3<>"",F3="No") | Y3: =AND(OR(B3<>"",D3<>""),F3="No") | Z3: =AND(B3<>"",E3<>"",F3="No") | AA3: =AND(OR(B3<>"",E3<>""),F3="No") | AB3: =AND(C3<>"",D3<>"",F3="No") | AC3: =AND(OR(C3<>"",D3<>""),F3="No") | AD3: =AND(C3<>"",E3<>"",F3="No") | AE3: =AND(OR(C3<>"",E3<>""),F3="No") | AF3: =AND(D3<>"",E3<>"",F3="No") | AG3: =AND(OR(D3<>"",E3<>""),F3="No")
A4: H.2.2 | D4: X | F4: No | H4: =AND(B4<>"",C4<>"") | I4: =OR(B4<>"",C4<>"") | J4: =AND(B4<>"",D4<>"") | K4: =OR(B4<>"",D4<>"") | L4: =AND(B4<>"",E4<>"") | M4: =OR(B4<>"",E4<>"") | N4: =AND(C4<>"",D4<>"") | O4: =OR(C4<>"",D4<>"") | P4: =AND(C4<>"",E4<>"") | Q4: =OR(C4<>"",E4<>"") | R4: =AND(D4<>"",E4<>"") | S4: =OR(D4<>"",E4<>"") | V4: =AND(B4<>"",C4<>"",F4="No") | W4: =AND(OR(B4<>"",C4<>""),F4="No") | X4: =AND(B4<>"",D4<>"",F4="No") | Y4: =AND(OR(B4<>"",D4<>""),F4="No") | Z4: =AND(B4<>"",E4<>"",F4="No") | AA4: =AND(OR(B4<>"",E4<>""),F4="No") | AB4: =AND(C4<>"",D4<>"",F4="No") | AC4: =AND(OR(C4<>"",D4<>""),F4="No") | AD4: =AND(C4<>"",E4<>"",F4="No") | AE4: =AND(OR(C4<>"",E4<>""),F4="No") | AF4: =AND(D4<>"",E4<>"",F4="No") | AG4: =AND(OR(D4<>"",E4<>""),F4="No")
A5: GS.2.3 | B5: X | F5: No | H5: =AND(B5<>"",C5<>"") | I5: =OR(B5<>"",C5<>"") | J5: =AND(B5<>"",D5<>"") | K5: =OR(B5<>"",D5<>"") | L5: =AND(B5<>"",E5<>"") | M5: =OR(B5<>"",E5<>"") | N5: =AND(C5<>"",D5<>"") | O5: =OR(C5<>"",D5<>"") | P5: =AND(C5<>"",E5<>"") | Q5: =OR(C5<>"",E5<>"") | R5: =AND(D5<>"",E5<>"") | S5: =OR(D5<>"",E5<>"") | V5: =AND(B5<>"",C5<>"",F5="No") | W5: =AND(OR(B5<>"",C5<>""),F5="No") | X5: =AND(B5<>"",D5<>"",F5="No") | Y5: =AND(OR(B5<>"",D5<>""),F5="No") | Z5: =AND(B5<>"",E5<>"",F5="No") | AA5: =AND(OR(B5<>"",E5<>""),F5="No") | AB5: =AND(C5<>"",D5<>"",F5="No") | AC5: =AND(OR(C5<>"",D5<>""),F5="No") | AD5: =AND(C5<>"",E5<>"",F5="No") | AE5: =AND(OR(C5<>"",E5<>""),F5="No") | AF5: =AND(D5<>"",E5<>"",F5="No") | AG5: =AND(OR(D5<>"",E5<>""),F5="No")
A6: L0_ii.2.1; L0_iii.2.2 | C6: X | D6: X | F6: Yes | H6: =AND(B6<>"",C6<>"") | I6: =OR(B6<>"",C6<>"") | J6: =AND(B6<>"",D6<>"") | K6: =OR(B6<>"",D6<>"") | L6: =AND(B6<>"",E6<>"") | M6: =OR(B6<>"",E6<>"") | N6: =AND(C6<>"",D6<>"") | O6: =OR(C6<>"",D6<>"") | P6: =AND(C6<>"",E6<>"") | Q6: =OR(C6<>"",E6<>"") | R6: =AND(D6<>"",E6<>"") | S6: =OR(D6<>"",E6<>"") | V6: =AND(B6<>"",C6<>"",F6="No") | W6: =AND(OR(B6<>"",C6<>""),F6="No") | X6: =AND(B6<>"",D6<>"",F6="No") | Y6: =AND(OR(B6<>"",D6<>""),F6="No") | Z6: =AND(B6<>"",E6<>"",F6="No") | AA6: =AND(OR(B6<>"",E6<>""),F6="No") | AB6: =AND(C6<>"",D6<>"",F6="No") | AC6: =AND(OR(C6<>"",D6<>""),F6="No") | AD6: =AND(C6<>"",E6<>"",F6="No") | AE6: =AND(OR(C6<>"",E6<>""),F6="No") | AF6: =AND(D6<>"",E6<>"",F6="No") | AG6: =AND(OR(D6<>"",E6<>""),F6="No")
A7: L0_ii.2.3 | C7: X | F7: Yes | H7: =AND(B7<>"",C7<>"") | I7: =OR(B7<>"",C7<>"") | J7: =AND(B7<>"",D7<>"") | K7: =OR(B7<>"",D7<>"") | L7: =AND(B7<>"",E7<>"") | M7: =OR(B7<>"",E7<>"") | N7: =AND(C7<>"",D7<>"") | O7: =OR(C7<>"",D7<>"") | P7: =AND(C7<>"",E7<>"") | Q7: =OR(C7<>"",E7<>"") | R7: =AND(D7<>"",E7<>"") | S7: =OR(D7<>"",E7<>"") | V7: =AND(B7<>"",C7<>"",F7="No") | W7: =AND(OR(B7<>"",C7<>""),F7="No") | X7: =AND(B7<>"",D7<>"",F7="No") | Y7: =AND(OR(B7<>"",D7<>""),F7="No") | Z7: =AND(B7<>"",E7<>"",F7="No") | AA7: =AND(OR(B7<>"",E7<>""),F7="No") | AB7: =AND(C7<>"",D7<>"",F7="No") | AC7: =AND(OR(C7<>"",D7<>""),F7="No") | AD7: =AND(C7<>"",E7<>"",F7="No") | AE7: =AND(OR(C7<>"",E7<>""),F7="No") | AF7: =AND(D7<>"",E7<>"",F7="No") | AG7: =AND(OR(D7<>"",E7<>""),F7="No")
A8: L0_iii.2.5 | D8: X | F8: Yes | H8: =AND(B8<>"",C8<>"") | I8: =OR(B8<>"",C8<>"") | J8: =AND(B8<>"",D8<>"") | K8: =OR(B8<>"",D8<>"") | L8: =AND(B8<>"",E8<>"") | M8: =OR(B8<>"",E8<>"") | N8: =AND(C8<>"",D8<>"") | O8: =OR(C8<>"",D8<>"") | P8: =AND(C8<>"",E8<>"") | Q8: =OR(C8<>"",E8<>"") | R8: =AND(D8<>"",E8<>"") | S8: =OR(D8<>"",E8<>"") | V8: =AND(B8<>"",C8<>"",F8="No") | W8: =AND(OR(B8<>"",C8<>""),F8="No") | X8: =AND(B8<>"",D8<>"",F8="No") | Y8: =AND(OR(B8<>"",D8<>""),F8="No") | Z8: =AND(B8<>"",E8<>"",F8="No") | AA8: =AND(OR(B8<>"",E8<>""),F8="No") | AB8: =AND(C8<>"",D8<>"",F8="No") | AC8: =AND(OR(C8<>"",D8<>""),F8="No") | AD8: =AND(C8<>"",E8<>"",F8="No") | AE8: =AND(OR(C8<>"",E8<>""),F8="No") | AF8: =AND(D8<>"",E8<>"",F8="No") | AG8: =AND(OR(D8<>"",E8<>""),F8="No")
